Workbook

Sheet 00_README
A1: BOURACKA-TESTPLAN — v0.4.3 (master + branch tagging + bug dedup + TES)
A3: Version | B3: v0.4.3
A4: Iteration | B4: CP-SUPIN-02 — deep public recon + Excel TestPlan v0.1 seeded
A5: Owner | B5: Petr Žemla (operator); ThinkPad Opus task-force (author)
A6: Created | B6: 46147
A7: Review | B7: Kateřina Pankratova
A8: Methodology | B8: CAST-static layer; methodology-neutral (R-METH-1..4)
A9: Frameworks | B9: Cypress + Playwright primary; TestCafe fallback (per §3.3 gates)
A10: Envs | B10: TEST (tst.bouracka.cz) + DEMO (tst.demo.bouracka.cz) + public (dev-time only)
A11: Locale | B11: Czech-first (cs_CZ); English-second
A12: Mobile-first | B12: Viewport spec 320 / 375 / 414 + desktop (per AMENDMENT 2)
A13: Reading order | B13: 00_README → 04_TestEnvironments → 01_TestTargets → 02_TestCases → 03_TestData → 05_TestSets → 06_TestRuns → 07_TestRunResults → 08_Bugs → 09_Reports → 10_Glossary → 11_Changelog
A14: Confidentiality | B14: Recon material gitignored on dev side per scope §7. THIS workbook is OK to commit (no client-confidential data).
A15: MI-M-T mapping | B15: Each entity sheet's columns mirror MI-M-T schema; ItemBase block is column 1..13 + 'created_at, updated_at, notes' tail.
A16: Priority Matrix | B16: Severity (A/B/C/D) × Urgency (A/B/C/D) → Priority computed in the 'priority' column per PRIORITY-MATRIX-GOVERNANCE §1.1.
A19: Legend
A20: severity / urgency | B20: A = Major, B = Standard, C = Minor, D = Undefined
A21: priority | B21: Computed: Sev+Urg sum → 2..3=A, 4=B, 5..6=C, any D=D
A22: verdict | B22: pass / fail / skip / blocked / partial
A23: decomposition_kind | B23: page / behaviour / component / integration / regression / smoke (R-CAST-1)
A24: step_kind | B24: control_point / trigger_point / data_collection_point / assertion (R-CAST-2)
A25: type | B25: happy / failure / regression / smoke
A26: R-FAIL-1 | B26: Every happy-path scenario MUST be paired with ≥ 1 failure scenario by iteration close.
A27: R-STRUCT-1/2 | B27: Replacement spec must list NEW / REPLACED / UNCHANGED. Migration ≠ duplication.

Sheet 00b_Requirements
A1: id | B1: item_code | C1: item_name_cs | D1: item_name_en | E1: item_descr_cs | F1: item_descr_en | G1: requirement_kind | H1: furps_dimensions | I1: source_artefact_kind | J1: source_artefact_ref | K1: severity | L1: urgency | M1: priority | N1: submitter | O1: submit_date | P1: notes | Q1: applies_to_demo | R1: applies_to_prod
A2: 1 | B2: REQ-CP-001 | C2: Brána aplikace je dostupná | D2: Application gateway is reachable | E2: Vstupní URL bouracka.cz/formular musí vrátit 2xx s render H1. | F2: Entry URL bouracka.cz/formular must return 2xx with rendered H1. | G2: functional | H2: F,R | I2: analytical_doc | J2: p13/133 §3.1 area A | K2: A | L2: A | M2: A | N2: Petr | O2: 46148 | Q2: TRUE | R2: TRUE
A3: 2 | B3: REQ-CP-002 | C3: SMS Gateway PING před vstupem | D3: SMS Gateway PING before entry | E3: Aplikace ověří dostupnost SMS Gateway před přechodem do NEW stavu. | F3: App PINGs SMS Gateway before transition to NEW state. | G3: functional | H3: F,R | I3: analytical_doc | J3: p25-29/133 (state machine entry) | K3: A | L3: A | M3: A | N3: Petr | O3: 46148 | Q3: TRUE | R3: TRUE
A4: 3 | B4: REQ-CP-003 | C4: Implicitní autentizace přes ID v registrech | D4: Implicit ID-auth via Czech registries | E4: Identita účastníka se ustaví scan OP+ŘP+SPZ → AISPOV (ROB+CRR+CRV). | F4: Participant identity established by OP+ŘP+SPZ scan → AISPOV (ROB+CRR+CRV). | G4: functional | H4: F,S,+L | I4: user_direction | J4: 2026-05-05 OQ-CP-12 closure | K4: A | L4: A | M4: A | N4: Petr | O4: 46148 | Q4: TRUE | R4: TRUE
A5: 4 | B5: REQ-CP-004 | C5: Mobilní viewport jako jediný cíl | D5: Mobile-only viewport target | E5: Aplikace renderuje pouze pro mobilní zobrazení (320/375/414 px). | F5: App renders only for mobile viewports (320/375/414 px). | G5: non-functional | H5: U,+I | I5: analytical_doc | J5: p14/133 §3.2 | K5: A | L5: B | M5: A | N5: Petr | O5: 46148 | Q5: TRUE | R5: TRUE
A6: 5 | B6: REQ-CP-005 | C6: CS lokalizace primárně | D6: CS-locale primary | E6: Všechny chybové hlášky a UI texty v CS, dle glosáře. | F6: All error messages + UI text in CS per glossary. | G6: non-functional | H6: U,S,+L | I6: scope_doc | J6: CLIENT-PILOT-SUPIN §C-6 | K6: A | L6: A | M6: A | N6: Petr | O6: 46148 | Q6: TRUE | R6: TRUE
A7: 6 | B7: REQ-CP-006 | C7: AISPOV ROB lookup auto-fill | D7: AISPOV ROB lookup auto-fill | E7: Po OCR OP aplikace volá AISPOV ROB; happy → form pre-filled. | F7: After OP OCR app calls AISPOV ROB; happy → form pre-filled. | G7: functional | H7: F,P | I7: analytical_doc | J7: p33-35/133 | K7: A | L7: A | M7: A | N7: Petr | O7: 46148 | Q7: TRUE | R7: TRUE
A8: 7 | B8: REQ-CP-007 | C8: AISPOV CRR lookup auto-fill | D8: AISPOV CRR lookup auto-fill | E8: Po ROB happy aplikace volá CRR; vrací řidičské oprávnění. | F8: After ROB happy app calls CRR; returns driver-license groups. | G8: functional | H8: F,P | I8: analytical_doc | J8: p35/133 | K8: A | L8: A | M8: A | N8: Petr | O8: 46148 | Q8: TRUE | R8: TRUE
A9: 8 | B9: REQ-CP-008 | C9: AISPOV CRV vehicle lookup | D9: AISPOV CRV vehicle lookup | E9: Po SPZ OCR aplikace volá CRV; auto-fill vozidlových dat. | F9: After SPZ OCR app calls CRV; auto-fill vehicle data. | G9: functional | H9: F,P | I9: analytical_doc | J9: p40/133 | K9: A | L9: A | M9: A | N9: Petr | O9: 46148 | Q9: TRUE | R9: TRUE
A10: 9 | B10: REQ-CP-009 | C10: Pojišťovna lookup s STATUS=AKT filtrem | D10: Insurer lookup with STATUS=AKT filter | E10: Combobox pojišťoven nabízí pouze pojišťovny s STATUS='AKT' v číselníku. | F10: Insurer combobox offers only STATUS='AKT' entries from codelist. | G10: functional | H10: F,S,+L | I10: field_definitions | J10: F-104, F-108 | K10: A | L10: B | M10: A | N10: Petr | O10: 46148 | Q10: TRUE | R10: TRUE
A11: 10 | B11: REQ-CP-010 | C11: SMS-OTP podpis obou účastníků | D11: SMS-OTP signing by both participants | E11: Před přechodem do FINISHED oba účastníci podepíší přes SMS-OTP. | F11: Before transition to FINISHED both participants sign via SMS-OTP. | G11: functional | H11: F,S,+L | I11: analytical_doc | J11: p41-42/133 area D | K11: A | L11: A | M11: A | N11: Petr | O11: 46148 | Q11: TRUE | R11: TRUE
A12: 11 | B12: REQ-CP-011 | C12: PDF generování + dispatch dvou e-mailů | D12: PDF generation + 2-email dispatch | E12: Po podpisu se vygeneruje PDF a odešle oběma účastníkům + pojišťovnám. | F12: After signing, PDF generated and dispatched to both participants + insurers. | G12: functional | H12: F,R | I12: analytical_doc | J12: p42/133 area D step 12 | K12: A | L12: B | M12: A | N12: Petr | O12: 46148 | Q12: TRUE | R12: TRUE
A13: 12 | B13: REQ-CP-012 | C13: ID hlášení DN jako QR pro IZS | D13: Report ID as QR for IRS | E13: Po podpisu PDF obsahuje QR + ID hlášení DN čitelný pro IZS. | F13: After signing PDF contains QR + report ID readable by IRS. | G13: functional | H13: F,+L | I13: analytical_doc | J13: p21/133 §3.3.2.4 | K13: A | L13: B | M13: A | N13: Petr | O13: 46148 | Q13: TRUE | R13: TRUE
... A21: 20 | B21: REQ-CP-020 | C21: Privacy: zenID neukládá OP na zařízení | D21: Privacy: zenID does not persist OP on device | E21: Při využití zenID WebSDK se OP účastníků neukládá na zařízení. | F21: When using zenID WebSDK OP is not persisted on participant device. | G21: non-functional | H21: S,+L | I21: analytical_doc | J21: p14/133 §3.2 | K21: A | L21: A | M21: A | N21: Petr | O21: 46148 | Q21: TRUE | R21: TRUE

Sheet 00c_VersionSanityRules
A1: Version sanity rules (must hold after every rev)
A3: 1. 00_README!A1 must contain the current version string (e.g. "v0.3.2")
A4: 2. 00_README!B3 must contain the full version (e.g. "v0.3.2.0")
A5: 3. 11_Changelog!A{last} must reference the same version
A6: 4. priority column must NOT contain formulas (use static values from MATRIX)
A7: 5. updated_at column must equal the rev date for any row touched
A8: 6. severity ∈ {A, B, C, D} and urgency ∈ {A, B, C, D} for every row that has both
A9: 7. priority must equal MATRIX[severity][urgency] for every row that has sev+urg
A11: Validator: tools/check_priority_matrix.py + tools/validate_workbook.py
A12: Migration tools: tools/migrate_to_v0X.py + tools/bump_workbook_version.py

Sheet 01_TestTargets
A1: id | B1: item_code | C1: item_name_cs | D1: item_name_en | E1: item_descr_cs | F1: item_descr_en | G1: item_type | H1: item_status | I1: severity | J1: urgency | K1: priority | L1: submitter | M1: submit_date | N1: release | O1: decomposition_kind | P1: component_ref | Q1: behaviour_ref | R1: coverage_basis | S1: env_coverage | T1: state_machine_terminal_state | U1: related_screen_refs | V1: related_flow_refs | W1: related_integration_refs | X1: created_at | Y1: updated_at | Z1: notes | AA1: furps_dimensions | AB1: co_what | AC1: kdo_who | AD1: kdy_when | AE1: kde_where | AF1: jak_how | AG1: source_artefact_kind | AH1: source_artefact_ref | AI1: derivation_rule | AJ1: source_artefact_author_role | AK1: requirement_ref | AL1: applies_to_demo | AM1: applies_to_prod
A2: 1 | B2: TT-CP-R1-A1 | C2: Vstupní brána a SMS-PING (screen 01) | D2: Wizard entry + SMS-Gateway PING (screen 01) | E2: Screen 01 transition: PING SMS Gateway → pokud OK → vytvoří ID hlášení (NEW); pokud NOK → ERROR Endpage. | F2: Screen 01 transition: PING SMS Gateway → if OK → create report ID (NEW); if NOK → ERROR Endpage. | G2: test_target | H2: active | I2: A | J2: A | K2: A | L2: Petr | M2: 46147 | N2: R1 | O2: behaviour | Q2: gate-on-sms-gateway-availability | R2: Pre-flight gate; failure here is a hard stop (ERROR Endpage). Smallest possible R1 unit. | S2: TST + DMO | T2: NEW | U2: SCR-002 + SCR-017 | V2: FLW-A1 | W2: INT-002 SMS Gateway | X2: 46147 | Y2: 46148 | Z2: Replaces rev3 TT-CP-R1-001 (split per OQ-CP-17). | AA2: F,R | AB2: PING SMS Gateway | AC2: SUT before NEW transition | AD2: screen 01 → 02 | AE2: wizard gateway entry | AF2: auto via Mockoon mock or real N8 | AG2: analytical_doc | AH2: p27/133 §3.1 | AI2: Pre-flight gate to verify SMS Gateway availability before issuing OTP requests. | AJ2: SUPIN | AK2: REQ-CP-002 | AL2: TRUE | AM2: TRUE
A3: 2 | B3: TT-CP-R1-A2 | C3: Ověření telefonních čísel (screen 02) | D3: Phone-OTP participant verification (screen 02) | E3: Ověření obou účastníků pomocí SMS OTP; CZ +420 / SK +421 prefix validation; konfigurovatelné limity (pokusy ověření / resend / change phone); reCaptcha; bezpečnostní DB-frequency check. | F3: Both participants verified via SMS OTP; CZ +420 / SK +421 prefix validation; configurable retry limits; reCaptcha; security DB-frequency check. | G3: test_target | H3: active | I3: A | J3: A | K3: A | L3: Petr | M3: 46147 | N3: R1 | O3: behaviour | Q3: verify-participants-via-otp | R3: State transition NEW → IN_PROGRESS_DRIVERS. Failure modes: SMS_CODE_ATTEMPTS, TELEPHONE_NUMBER_COUNT, HTTP-422 EX_CHYBA. R-FAIL-1 mandatory. | S3: TST + DMO | T3: IN_PROGRESS_DRIVERS | U3: SCR-018 | V3: FLW-A2 | W3: INT-001 reCaptcha + INT-002 SMS Gateway | X3: 46147 | Y3: 46148 | Z3: Czech mobile prefix list + SK 9-digit validated client-side. | AA3: F,R,S | AB3: Phone-OTP verification both participants | AC3: user via SUT | AD3: screen 02 | AE3: phone-input + OTP entry forms | AF3: auto via Mockoon SEND_OTP+VALIDATE_OTP | AG3: analytical_doc | AH3: p27-29/133 | AI3: Both participants must be verified via SMS-OTP before app advances to IN_PROGRESS_DRIVERS. | AJ3: SUPIN | AK3: REQ-CP-002 | AL3: TRUE | AM3: TRUE
A4: 3 | B4: TT-CP-R1-B | C4: Načtení dat řidiče (zenID + AISPOV; screens 03–06) | D4: Driver data load via zenID + AISPOV (screens 03–06) | E4: Implicitní ID-autentizace: zenID OCR (WebSDK kamera nebo API galerie) → AISPOV (ROB + CRR) → auto-fill or editing-mode podle StatusVysledek. | F4: Implicit ID-auth: zenID OCR (WebSDK camera or API gallery) → AISPOV (ROB + CRR) → auto-fill or editing-mode by StatusVysledek. | G4: test_target | H4: active | I4: A | J4: A | K4: A | L4: Petr | M4: 46147 | N4: R1 | O4: behaviour | Q4: load-driver-data-from-zenid-aispov | R4: THE 'implicit ID-based authentication' per user direction 2026-05-05. Internal to IN_PROGRESS_DRIVERS. AISPOV call-count cap is config-limited. | S4: TST + DMO | T4: IN_PROGRESS_DRIVERS | U4: SCR-019 + SCR-020 (driver A) + SCR-021 + SCR-022 (driver N) | V4: FLW-B | W4: INT-006 + INT-007 zenID + INT-004 AISPOV + INT-008 RUIAN | X4: 46147 | Y4: 46148 | Z4: data_source annotation: zenid|aispov|manual|mixed. | AA4: F,P,S,+L | AB4: Driver-data load via OCR + AISPOV ROB+CRR | AC4: user via SUT + AISPOV | AD4: screens 03–06 | AE4: OP/ŘP scan + auto-fill form | AF4: auto via zenID + AISPOV mocks | AG4: analytical_doc | AH4: p30-35/133 | AI4: Implicit ID-auth per user direction 2026-05-05 OQ-CP-12 closure. | AJ4: SUPIN | AK4: REQ-CP-003 | AL4: TRUE | AM4: TRUE
A5: 4 | B5: TT-CP-R1-C | C5: SPZ + údaje o vozidle (zenID + AISPOV; screens 08–11) | D5: SPZ + vehicle data load via zenID + AISPOV (screens 08–11) | E5: zenID SPZ scan → confirmation popup → AISPOV (vehicle + insurance) → auto-fill or editing-mode. Damage marking + collision-position photos. | F5: zenID SPZ scan → confirmation popup → AISPOV (vehicle + insurance) → auto-fill or editing-mode. Damage marking + collision-position photos. | G5: test_target | H5: active | I5: A | J5: A | K5: A | L5: Petr | M5: 46147 | N5: R1 | O5: behaviour | Q5: load-vehicle-data-from-zenid-aispov | R5: State transition IN_PROGRESS_VEHICLES → IN_PROGRESS_CIRCUMSTANCES. SPZ irreversible once OCR'd. | S5: TST + DMO | T5: IN_PROGRESS_CIRCUMSTANCES | U5: SCR-023 + SCR-024 | V5: FLW-C | W5: INT-006 + INT-007 zenID + INT-004 AISPOV | X5: 46147 | Y5: 46148 | Z5: Photo limits config-driven: SPZ=1; damage+collision share max-N minus 1. | AA5: F,P | AB5: Vehicle data load via SPZ scan + AISPOV CRV | AC5: user via SUT + AISPOV | AD5: screens 08–11 | AE5: SPZ scan + vehicle form | AF5: auto via zenID + AISPOV mocks | AG5: analytical_doc | AH5: p36-40/133 | AI5: Vehicle identity via SPZ → CRV; insurance via Evidence pojištěných vozidel. | AJ5: SUPIN | AK5: REQ-CP-008 | AL5: TRUE | AM5: TRUE
A6: 5 | B6: TT-CP-R1-D | C6: Okolnosti, datum, místo, viník, souhrn, podpis (screens 12–18) | D6: Circumstances, date/time, location, fault, summary, sign (screens 12–18) | E6: Popis okolností; geolokace + manuální adresa; určení viníka; souhrn; SMS-OTP podpis obou řidičů; PDF + e-mail dispatch. | F6: Circumstances; geocode/manual address; fault determination; summary; SMS-OTP both-driver signing; PDF + e-mail dispatch. | G6: test_target | H6: active | I6: A | J6: A | K6: A | L6: Petr | M6: 46147 | N6: R1 | O6: behaviour | Q6: complete-circumstances-and-sign | R6: State transitions IN_PROGRESS_CIRCUMSTANCES → TO_SIGN → FINISHED. Closes the report; produces PDF + sends 2 e-mails. | S6: TST + DMO | T6: FINISHED | U6: SCR-025..SCR-031 | V6: FLW-D | W6: INT-002 SMS sign + INT-003 SMTP + INT-005 Maps | X6: 46147 | Y6: 46148 | Z6: OTP exhaustion at sign step → ERROR; submit timeout → recoverable retry. | AA6: F,U,R,S,+L | AB6: Circumstances + sign + complete | AC6: both participants via SMS-OTP | AD6: screens 12–18 | AE6: summary + signing + dispatch | AF6: auto via maps/RUIAN mocks + SMS sign + SMTP | AG6: analytical_doc | AH6: p40-42/133 | AI6: Closing sequence transitions IN_PROGRESS_CIRCUMSTANCES → TO_SIGN → FINISHED. | AJ6: SUPIN | AK6: REQ-CP-010 | AL6: TRUE | AM6: TRUE
A7: 6 | B7: TT-CP-R1-E | C7: End-to-end orchestrace (cross-area) | D7: End-to-end happy orchestration (cross-area) | E7: Plný happy průchod od NEW přes všechny stavy do FINISHED, validuje cross-area integrace + state-machine progression. | F7: Full happy run NEW → FINISHED across all areas; validates cross-area integration + state-machine progression. | G7: test_target | H7: active | I7: A | J7: B | K7: A | L7: Petr | M7: 46147 | N7: R1 | O7: behaviour | Q7: submit-traffic-accident-record-end-to-end | R7: Catches integration-orchestration regressions (e.g. TT-CP-R1-A2 + B work in isolation but fail together). | S7: TST + DMO | T7: FINISHED | U7: SCR-002..SCR-031 | V7: FLW-E | W7: INT-001..INT-010 (all) | X7: 46147 | Y7: 46148 | Z7: Single TC suffices; expensive but high-value sentinel. | AA7: F,R | AB7: End-to-end happy orchestration | AC7: both participants | AD7: full wizard NEW → FINISHED | AE7: all screens | AF7: auto cross-area | AG7: state_machine | AH7: accidentReportStatus full traversal | AI7: Catches integration-orchestration regressions across all areas. | AJ7: ThinkPad | AK7: REQ-CP-001 | AL7: TRUE | AM7: TRUE
A8: 7 | B8: TT-CP-R1-F | C8: Obálka chyb a ukončení (cross-area) | D8: Failure + termination envelope (cross-area) | E8: Recoverable retries (OTP retry, OCR retry, server timeout) + irrecoverable terminations (eligibility, OTP exhaustion, mid-wizard interlock self-disclosure, outage active). | F8: Recoverable retries + irrecoverable terminations across the wizard. | G8: test_target | H8: active | I8: A | J8: A | K8: A | L8: Petr | M8: 46147 | N8: R1 | O8: behaviour | Q8: handle-wizard-exceptions-and-terminations | R8: Pairs cross-area failure modes with happy peers per R-FAIL-1. | S8: TST + DMO | T8: ERROR (with sub-reasons) | U8: SCR-002 + SCR-015 + SCR-018 | V8: FLW-F | W8: INT-002 + INT-004 + INT-009 | X8: 46147 | Y8: 46148 | Z8: Includes outage-active and Azure Blob config error paths. | AA8: F,R,S,+L | AB8: Failure envelope cross-area | AC8: various | AD8: any state | AE8: any screen | AF8: auto with fault injection | AG8: state_machine | AH8: ERROR sub-reasons | AI8: Pairs with happy peers per R-FAIL-1; covers OUTAGE_ACTIVE, ELIGIBILITY_INTERLOCK, PING_NOK. | AJ8: ThinkPad | AK8: REQ-CP-014 | AL8: TRUE | AM8: TRUE
A9: 8 | B9: TT-CP-R2-COOKIE | C9: Cookies banner first-visit | D9: Cookies banner first-visit | E9: Cross-cutting first-visit smoke; reject-all branch. | F9: First-visit smoke; reject-all path. | G9: test_target | H9: draft | I9: C | J9: B | K9: C | L9: Petr | M9: 46147 | N9: R2 | O9: component | P9: cookie-banner | R9: GDPR compliance smoke; not in R1 envelope. | S9: TST + DMO + PUB(dev) | T9: n/a | U9: SCR-016 | W9: INT-010 GA | X9: 46147 | Y9: 46148 | Z9: Identified for later. | AA9: F | AB9: (R2 — to define) | AC9: (R2) | AD9: (R2) | AE9: (R2) | AF9: (R2) | AG9: user_direction | AH9: deferred per OQ-CP-OREV-05 | AI9: R2 deferred — full provenance authored when promoted to R1. | AJ9: ThinkPad | AK9: REQ-CP-001 | AL9: TRUE | AM9: TRUE
A10: 9 | B10: TT-CP-R2-OUTAGE-WARN | C10: Plánovaná odstávka (žlutý box) | D10: Planned outage (yellow box) | E10: Pre-outage warning rendered v rámci `from − warning_before_hours .. from`. | F10: Pre-outage warning in `from − warning_before_hours .. from` window. | G10: test_target | H10: draft | I10: B | J10: C | K10: C | L10: Petr | M10: 46147 | N10: R2 | O10: behaviour | Q10: render-planned-outage-warning | R10: Separate from R1-F outage-active (which disables CTA). This is the warning state. | S10: TST + DMO + PUB(dev) | T10: n/a | U10: SCR-002 | W10: INT-009 Azure Blob outage | X10: 46147 | Y10: 46148 | Z10: Clock-mock or fixture-time required to test reliably. | AA10: F | AB10: (R2 — to define) | AC10: (R2) | AD10: (R2) | AE10: (R2) | AF10: (R2) | AG10: user_direction | AH10: deferred per OQ-CP-OREV-05 | AI10: R2 deferred — full provenance authored when promoted to R1. | AJ10: ThinkPad | AK10: REQ-CP-001 | AL10: TRUE | AM10: TRUE
A11: 10 | B11: TT-CP-R2-SHARED | C11: Sdílený záznam (link/QR pro účastníka N) | D11: Shared record (link/QR for participant N) | E11: Generated on screen 15; default 60 min lifetime; review-only; PDF download; expired-link UX. | F11: Generated on screen 15; default 60 min; review-only; PDF download; expired-link UX. | G11: test_target | H11: draft | I11: B | J11: C | K11: C | L11: Petr | M11: 46147 | N11: R2 | O11: behaviour | Q11: share-record-with-participant-n | R11: Cross-device wizard handoff; secondary to R1. | S11: TST + DMO | T11: TO_SIGN | FINISHED | CANCEL | ERROR | U11: SCR-014 | X11: 46147 | Y11: 46148 | Z11: Identified for later. | AA11: F | AB11: (R2 — to define) | AC11: (R2) | AD11: (R2) | AE11: (R2) | AF11: (R2) | AG11: user_direction | AH11: deferred per OQ-CP-OREV-05 | AI11: R2 deferred — full provenance authored when promoted to R1. | AJ11: ThinkPad | AK11: REQ-CP-001 | AL11: TRUE | AM11: TRUE
A12: 11 | B12: TT-CP-R2-MENU | C12: In-app menu (sidebar/hamburger) | D12: In-app sidebar/hamburger menu | E12: Section progression — sections become clickable as user fills them; Začít znovu confirmation logic. | F12: Section progression; Začít znovu confirmation. | G12: test_target | H12: draft | I12: B | J12: C | K12: C | L12: Petr | M12: 46147 | N12: R2 | O12: component | P12: wizard-sidebar-menu | R12: Navigation correctness across state machine; secondary to R1. | S12: TST + DMO | T12: any | U12: SCR-013 | X12: 46147 | Y12: 46148 | Z12: Identified for later. | AA12: F | AB12: (R2 — to define) | AC12: (R2) | AD12: (R2) | AE12: (R2) | AF12: (R2) | AG12: user_direction | AH12: deferred per OQ-CP-OREV-05 | AI12: R2 deferred — full provenance authored when promoted to R1. | AJ12: ThinkPad | AK12: REQ-CP-001 | AL12: TRUE | AM12: TRUE
A13: 12 | B13: TT-CP-R2-FAQ | C13: FAQ — taxonomie a obsah | D13: FAQ — taxonomy + content | E13: /faq accordion smoke; 6 categories. | F13: /faq accordion smoke; 6 categories. | G13: test_target | H13: draft | I13: B | J13: C | K13: C | L13: Petr | M13: 46147 | N13: R2 | O13: page | P13: faq-page | Q13: browse-faq-content | R13: Cheap CMS sentinel. | S13: TST + DMO + PUB(dev) | T13: n/a | U13: SCR-003 | V13: FLW-005 | X13: 46147 | Y13: 46148 | Z13: Was rev3 TT-CP-R2-003. | AA13: F | AB13: (R2 — to define) | AC13: (R2) | AD13: (R2) | AE13: (R2) | AF13: (R2) | AG13: user_direction | AH13: deferred per OQ-CP-OREV-05 | AI13: R2 deferred — full provenance authored when promoted to R1. | AJ13: ThinkPad | AK13: REQ-CP-001 | AL13: TRUE | AM13: TRUE
A14: 13 | B14: TT-CP-R2-LANDING | C14: Landing — marketing surface | D14: Landing — marketing surface | E14: Landing page smoke; primary CTA destination. | F14: Landing page smoke. | G14: test_target | H14: draft | I14: C | J14: C | K14: D | L14: Petr | M14: 46147 | N14: R2 | O14: page | P14: landing-page-with-hero | Q14: browse-product-information | R14: Cheap CMS sentinel; pre-ID-auth surface. | S14: TST + DMO + PUB(dev) | T14: n/a | U14: SCR-001 | W14: INT-009 + INT-010 | X14: 46147 | Y14: 46148 | Z14: Was rev3 TT-CP-R2-005. | AA14: F | AB14: (R2 — to define) | AC14: (R2) | AD14: (R2) | AE14: (R2) | AF14: (R2) | AG14: user_direction | AH14: deferred per OQ-CP-OREV-05 | AI14: R2 deferred — full provenance authored when promoted to R1. | AJ14: ThinkPad | AK14: REQ-CP-001 | AL14: TRUE | AM14: TRUE
A15: 14 | B15: TT-CP-R2-HEADER | C15: Záhlaví / hamburger cross-page | D15: Header / hamburger cross-page | E15: Persistent UI surface across all pages; mobile-first viewport sweep. | F15: Persistent UI; mobile-first sweep. | G15: test_target | H15: draft | I15: B | J15: D | K15: D | L15: Petr | M15: 46147 | N15: R2 | O15: component | P15: site-header-with-hamburger-and-cta | R15: WCAG touch-target sentinel. | S15: TST + DMO + PUB(dev) | T15: n/a | U15: SCR-004 | X15: 46147 | Y15: 46148 | Z15: Was rev3 TT-CP-R2-004. | AA15: F | AB15: (R2 — to define) | AC15: (R2) | AD15: (R2) | AE15: (R2) | AF15: (R2) | AG15: user_direction | AH15: deferred per OQ-CP-OREV-05 | AI15: R2 deferred — full provenance authored when promoted to R1. | AJ15: ThinkPad | AK15: REQ-CP-001 | AL15: TRUE | AM15: TRUE
A16: 15 | B16: TT-CP-R2-GDPR | C16: GDPR / personal-data stránka | D16: GDPR / personal-data page | E16: /formular/personal-data static page. | F16: Static doc page; smoke postačí. | G16: test_target | H16: draft | I16: C | J16: D | K16: D | L16: Petr | M16: 46147 | N16: R2 | O16: page | P16: formular-personal-data-page | R16: Static GDPR document. | S16: TST + DMO + PUB(dev) | T16: n/a | U16: SCR-005 | X16: 46147 | Y16: 46148 | Z16: Was rev3 TT-CP-R2-006. | AA16: F | AB16: (R2 — to define) | AC16: (R2) | AD16: (R2) | AE16: (R2) | AF16: (R2) | AG16: user_direction | AH16: deferred per OQ-CP-OREV-05 | AI16: R2 deferred — full provenance authored when promoted to R1. | AJ16: ThinkPad | AK16: REQ-CP-001 | AL16: TRUE | AM16: TRUE
A17: 16 | B17: TT-CP-R2-WITNESS | C17: Svědci nehody (screen 07) | D17: Witnesses (screen 07) | E17: Optional witness add; passenger-marking; witness CRUD. | F17: Witness add; passenger marking. | G17: test_target | H17: draft | I17: B | J17: C | K17: C | L17: Petr | M17: 46147 | N17: R2 | O17: behaviour | Q17: manage-witnesses | R17: Internal to IN_PROGRESS_DRIVERS → IN_PROGRESS_VEHICLES; mid-wizard but optional, hence R2. | S17: TST + DMO | T17: IN_PROGRESS_VEHICLES | U17: SCR-027 | X17: 46147 | Y17: 46148 | Z17: Could promote to R1 if business demands. | AA17: F | AB17: (R2 — to define) | AC17: (R2) | AD17: (R2) | AE17: (R2) | AF17: (R2) | AG17: user_direction | AH17: deferred per OQ-CP-OREV-05 | AI17: R2 deferred — full provenance authored when promoted to R1. | AJ17: ThinkPad | AK17: REQ-CP-001 | AL17: TRUE | AM17: TRUE
A18: 17 | B18: TT-CP-R2-DEMO-RELAX | C18: DEMO env redukovaná validace | D18: DEMO env relaxed validation | E18: Per scope C-5 — DEMO env vs TST env divergences (e.g. SPZ format, location bounds, OTP fixed=0000). | F18: Per scope C-5 — DEMO env vs TST env validation deltas. | G18: test_target | H18: draft | I18: B | J18: B | K18: B | L18: Petr | M18: 46147 | N18: R2 | O18: behaviour | Q18: compare-tst-vs-demo-validation | R18: Cross-cutting; R2 because depth pending tst.* recon. | S18: DMO (vs TST baseline) | T18: n/a | U18: all R1 SCR-NNN | W18: all integrations | X18: 46147 | Y18: 46148 | Z18: Bridges R1 + DEMO posture; lands once tst-demo recon arrives. | AA18: F | AB18: (R2 — to define) | AC18: (R2) | AD18: (R2) | AE18: (R2) | AF18: (R2) | AG18: user_direction | AH18: deferred per OQ-CP-OREV-05 | AI18: R2 deferred — full provenance authored when promoted to R1. | AJ18: ThinkPad | AK18: REQ-CP-001 | AL18: TRUE | AM18: FALSE
A19: 18 | B19: TT-CP-R2-VEHICLE-N | C19: Vozidlo N (screens 10–11) | D19: Vehicle N (screens 10–11) | E19: Replication of TT-CP-R1-C for second vehicle (participant N). | F19: Replicates vehicle-data-load behaviour for participant N. | G19: test_target | H19: draft | I19: A | J19: B | K19: A | L19: Petr | M19: 46147 | N19: R2 | O19: behaviour | Q19: load-vehicle-data-for-participant-n | R19: Subset of TT-CP-R1-C iteration; could be folded into TC-CP-018 E2E. | S19: TST + DMO | T19: IN_PROGRESS_CIRCUMSTANCES | U19: SCR-023b + SCR-024b | V19: FLW-C | W19: INT-006 + INT-007 + INT-004 | X19: 46147 | Y19: 46148 | Z19: Identified; depth covered by TC-CP-018 cross-area orchestration. | AA19: F | AB19: (R2 — to define) | AC19: (R2) | AD19: (R2) | AE19: (R2) | AF19: (R2) | AG19: user_direction | AH19: deferred per OQ-CP-OREV-05 | AI19: R2 deferred — full provenance authored when promoted to R1. | AJ19: ThinkPad | AK19: REQ-CP-001 | AL19: TRUE | AM19: TRUE
B20: TT-CP-PHASE0 | C20: Rozcestník + safety guidance | D20: Gateway page + safety guidance | K20: =IF(OR(I20="",J20=""),"D",IF((CODE(I20)+CODE(J20)-130)<=1,"A",IF((CODE(I20)+CODE(J20)-130)=2,"B",IF((CODE(I20)+CODE(J20)-130)=3,"C","D")))) -> D | Y20: 46148 | Z20: endpoints: (none — static SPA shell + outage feed INT-006) | screens: /formular/ rozcestník | AL20: TRUE | AM20: TRUE
B21: TT-CP-PHASE-A | C21: Pre-wizard intro | D21: Pre-wizard intro | K21: =IF(OR(I21="",J21=""),"D",IF((CODE(I21)+CODE(J21)-130)<=1,"A",IF((CODE(I21)+CODE(J21)-130)=2,"B",IF((CODE(I21)+CODE(J21)-130)=3,"C","D")))) -> D | Y21: 46148 | Z21: endpoints: POST /api/reports | screens: /formular/informations | AL21: TRUE | AM21: TRUE
B22: TT-CP-PHASE1 | C22: Phone verification (OTP rounds) | D22: Phone verification | K22: =IF(OR(I22="",J22=""),"D",IF((CODE(I22)+CODE(J22)-130)<=1,"A",IF((CODE(I22)+CODE(J22)-130)=2,"B",IF((CODE(I22)+CODE(J22)-130)=3,"C","D")))) -> D | Y22: 46148 | Z22: endpoints: PUT /reporter, POST /participants, POST /sendCodeToVerify, POST /verify, GET /participantsInVerification | screens: /verification + /verification/success | AL22: TRUE | AM22: TRUE
B23: TT-CP-PHASE2 | C23: Documents per participant (OP+ŘP+address+email) | D23: Documents per participant | K23: =IF(OR(I23="",J23=""),"D",IF((CODE(I23)+CODE(J23)-130)<=1,"A",IF((CODE(I23)+CODE(J23)-130)=2,"B",IF((CODE(I23)+CODE(J23)-130)=3,"C","D")))) -> D | Y23: 46148 | Z23: endpoints: PUT /participantData, /email, /drivingLicense/update + RUIAN INT-009 | screens: /documents/{p}/{...}/manual /recap | AL23: TRUE | AM23: TRUE
B24: TT-CP-PHASE2.5 | C24: Witnesses (optional) | D24: Witnesses | K24: =IF(OR(I24="",J24=""),"D",IF((CODE(I24)+CODE(J24)-130)<=1,"A",IF((CODE(I24)+CODE(J24)-130)=2,"B",IF((CODE(I24)+CODE(J24)-130)=3,"C","D")))) -> D | Y24: 46148 | Z24: endpoints: GET /witnesses (POST/PUT TBC) | screens: /witness | AL24: TRUE | AM24: TRUE
B25: TT-CP-PHASE3-PER | C25: Per-participant accident details | D25: Per-participant accident details | K25: =IF(OR(I25="",J25=""),"D",IF((CODE(I25)+CODE(J25)-130)<=1,"A",IF((CODE(I25)+CODE(J25)-130)=2,"B",IF((CODE(I25)+CODE(J25)-130)=3,"C","D")))) -> D | Y25: 46148 | Z25: endpoints: PUT damage, movementDefinition, vehicle, insurer + GET enumerations | screens: /accident/{p}/[damage|damage/movement|damage/data] | AL25: TRUE | AM25: TRUE
B26: TT-CP-PHASE3-SH | C26: Shared circumstances + place | D26: Shared circumstances + place | K26: =IF(OR(I26="",J26=""),"D",IF((CODE(I26)+CODE(J26)-130)<=1,"A",IF((CODE(I26)+CODE(J26)-130)=2,"B",IF((CODE(I26)+CODE(J26)-130)=3,"C","D")))) -> D | Y26: 46148 | Z26: endpoints: PUT circumstances, datetime, location, responsibleParticipant + INT-009 + INT-007 | screens: /accident/circumstances /situation /situation/location /culprit | AL26: TRUE | AM26: TRUE
B27: TT-CP-PHASE4 | C27: Sign + submit (dual SMS) | D27: Sign + submit | K27: =IF(OR(I27="",J27=""),"D",IF((CODE(I27)+CODE(J27)-130)<=1,"A",IF((CODE(I27)+CODE(J27)-130)=2,"B",IF((CODE(I27)+CODE(J27)-130)=3,"C","D")))) -> D | Y27: 46148 | Z27: endpoints: POST /confirmation, /sendCodeToSign, /sign + GET /summaryId | screens: /summary /sign-report /success | AL27: TRUE | AM27: TRUE
B28: TT-CP-IDENTIFIER | C28: Identifikační kód for Police/IZS | D28: Identifikační kód for Police/IZS | K28: =IF(OR(I28="",J28=""),"D",IF((CODE(I28)+CODE(J28)-130)<=1,"A",IF((CODE(I28)+CODE(J28)-130)=2,"B",IF((CODE(I28)+CODE(J28)-130)=3,"C","D")))) -> D | Y28: 46148 | Z28: endpoints: (rendered from report state — drives police on-scene lookup) | screens: (persistent modal across all post-Phase-1 routes) | AL28: TRUE | AM28: TRUE
B29: TT-CP-CODELISTS | C29: Codelist API surface | D29: Codelist API surface | K29: =IF(OR(I29="",J29=""),"D",IF((CODE(I29)+CODE(J29)-130)<=1,"A",IF((CODE(I29)+CODE(J29)-130)=2,"B",IF((CODE(I29)+CODE(J29)-130)=3,"C","D")))) -> D | Y29: 46148 | Z29: endpoints: GET /api/enumerations/* (selective public access) | screens: (used internally by Phase 2 + 3) | AL29: TRUE | AM29: TRUE

Sheet 00e_BranchView
A1: Branched master view — Bouračka (PROD) vs DEMO Bouračka
A3: Architecture
A4: Single master workbook — switch view via AutoFilter on applies_to_demo / applies_to_prod columns.
A5: Both branches share the same TestTargets / TestCases where env_constraints = "both" or "both-with-adapter".
A6: Rows specific to one branch are tagged via env_constraints (demo-only / prod-only).
A8: Counts per branch (entries with applies_to_X = TRUE)
A10: Sheet | B10: Total rows | C10: DEMO branch | D10: PROD branch | E10: DEMO-only | F10: PROD-only | G10: Both
A11: 00b_Requirements | B11: 20 | C11: 20 | D11: 20 | E11: 0 | F11: 0 | G11: 20
A12: 01_TestTargets | B12: 28 | C12: 28 | D12: 27 | E12: 1 | F12: 0 | G12: 27
A13: 02_TestCases | B13: 49 | C13: 47 | D13: 48 | E13: 1 | F13: 2 | G13: 46
A14: 08_Bugs | B14: 0 | C14: 0 | D14: 0 | E14: 0 | F14: 0 | G14: 0
A15: TOTAL | B15: 97 | C15: 95 | D15: 95 | G15: 93
A18: Jak přepnout pohled (CS)
A19: 1. Otevřete list (např. 02_TestCases).
A20: 2. Klikněte na šipku AutoFilter v záhlaví sloupce `applies_to_demo`.
A21: 3. Pro pohled "DEMO branch only" — zaškrtněte JEN TRUE.
A22: 4. Pro pohled "PROD branch only" — udělejte stejné na sloupci `applies_to_prod`.
A23: 5. Pro reset (zobrazit vše) — klikněte na šipku → "Vymazat filtr z..."
A25: Tip — pro rychlé přepnutí lze definovat Excel makro / VBA proceduru,
A26: která nastaví filtr na jednom místě a aplikuje napříč všemi listy.
A27: Vzor makra je v `_install/EXCEL-MACRO-BRANCH-FILTER.bas` (po roll-out).
A29: Sloupec env_constraints — co znamenají hodnoty (jen 02_TestCases)
A30: `both` — TC běží na obou branchech identicky (DEMO i PROD)
A31: `both-with-adapter` — TC běží na obou, na PROD s Mockoon / N8 sandbox adaptérem
... A33: `prod-only` — TC vyžaduje reálné integrace; na DEMO by produkoval false signal

Sheet 01b_Req_FURPS_Cartesian
A1: id | B1: requirement_ref | C1: furps_dimension | D1: cell_status | E1: na_justification | F1: scheduling_unit_kind | G1: severity | H1: urgency | I1: priority | J1: expected_tc_count | K1: notes
A2: 1 | B2: REQ-CP-001 | C2: F | D2: active | F2: iteration | G2: B | H2: B | I2: =IF(OR(G2="",H2=""),"D",IF(OR(G2="D",H2="D"),"D",IF((CODE(G2)+CODE(H2)-130)<=3,"A",IF((CODE(G2)+CODE(H2)-130)=4,"B","C")))) -> A | J2: 1
A3: 2 | B3: REQ-CP-001 | C3: U | D3: pending | F3: iteration | G3: C | H3: C | I3: =IF(OR(G3="",H3=""),"D",IF(OR(G3="D",H3="D"),"D",IF((CODE(G3)+CODE(H3)-130)<=3,"A",IF((CODE(G3)+CODE(H3)-130)=4,"B","C")))) -> B | J3: 0
A4: 3 | B4: REQ-CP-001 | C4: R | D4: active | F4: iteration | G4: B | H4: B | I4: =IF(OR(G4="",H4=""),"D",IF(OR(G4="D",H4="D"),"D",IF((CODE(G4)+CODE(H4)-130)<=3,"A",IF((CODE(G4)+CODE(H4)-130)=4,"B","C")))) -> A | J4: 1
A5: 4 | B5: REQ-CP-001 | C5: P | D5: pending | F5: iteration | G5: C | H5: C | I5: =IF(OR(G5="",H5=""),"D",IF(OR(G5="D",H5="D"),"D",IF((CODE(G5)+CODE(H5)-130)<=3,"A",IF((CODE(G5)+CODE(H5)-130)=4,"B","C")))) -> B | J5: 0
A6: 5 | B6: REQ-CP-001 | C6: S | D6: pending | F6: iteration | G6: C | H6: C | I6: =IF(OR(G6="",H6=""),"D",IF(OR(G6="D",H6="D"),"D",IF((CODE(G6)+CODE(H6)-130)<=3,"A",IF((CODE(G6)+CODE(H6)-130)=4,"B","C")))) -> B | J6: 0
A7: 6 | B7: REQ-CP-001 | C7: +D | D7: pending | F7: iteration | G7: C | H7: C | I7: =IF(OR(G7="",H7=""),"D",IF(OR(G7="D",H7="D"),"D",IF((CODE(G7)+CODE(H7)-130)<=3,"A",IF((CODE(G7)+CODE(H7)-130)=4,"B","C")))) -> B | J7: 0
A8: 7 | B8: REQ-CP-001 | C8: +I | D8: pending | F8: iteration | G8: C | H8: C | I8: =IF(OR(G8="",H8=""),"D",IF(OR(G8="D",H8="D"),"D",IF((CODE(G8)+CODE(H8)-130)<=3,"A",IF((CODE(G8)+CODE(H8)-130)=4,"B","C")))) -> B | J8: 0
A9: 8 | B9: REQ-CP-001 | C9: +N | D9: pending | F9: iteration | G9: C | H9: C | I9: =IF(OR(G9="",H9=""),"D",IF(OR(G9="D",H9="D"),"D",IF((CODE(G9)+CODE(H9)-130)<=3,"A",IF((CODE(G9)+CODE(H9)-130)=4,"B","C")))) -> B | J9: 0
A10: 9 | B10: REQ-CP-001 | C10: +L | D10: pending | F10: iteration | G10: C | H10: C | I10: =IF(OR(G10="",H10=""),"D",IF(OR(G10="D",H10="D"),"D",IF((CODE(G10)+CODE(H10)-130)<=3,"A",IF((CODE(G10)+CODE(H10)-130)=4,"B","C")))) -> B | J10: 0
A11: 10 | B11: REQ-CP-001 | C11: +P_phys | D11: na | E11: +P_phys (physical-hardware constraints) N/A for web SUT | F11: none | G11: D | H11: D | I11: =IF(OR(G11="",H11=""),"D",IF(OR(G11="D",H11="D"),"D",IF((CODE(G11)+CODE(H11)-130)<=3,"A",IF((CODE(G11)+CODE(H11)-130)=4,"B","C")))) -> D | J11: 0
A12: 11 | B12: REQ-CP-002 | C12: F | D12: active | F12: iteration | G12: B | H12: B | I12: =IF(OR(G12="",H12=""),"D",IF(OR(G12="D",H12="D"),"D",IF((CODE(G12)+CODE(H12)-130)<=3,"A",IF((CODE(G12)+CODE(H12)-130)=4,"B","C")))) -> A | J12: 1
A13: 12 | B13: REQ-CP-002 | C13: U | D13: pending | F13: iteration | G13: C | H13: C | I13: =IF(OR(G13="",H13=""),"D",IF(OR(G13="D",H13="D"),"D",IF((CODE(G13)+CODE(H13)-130)<=3,"A",IF((CODE(G13)+CODE(H13)-130)=4,"B","C")))) -> B | J13: 0
A14: 13 | B14: REQ-CP-002 | C14: R | D14: active | F14: iteration | G14: B | H14: B | I14: =IF(OR(G14="",H14=""),"D",IF(OR(G14="D",H14="D"),"D",IF((CODE(G14)+CODE(H14)-130)<=3,"A",IF((CODE(G14)+CODE(H14)-130)=4,"B","C")))) -> A | J14: 1
A15: 14 | B15: REQ-CP-002 | C15: P | D15: pending | F15: iteration | G15: C | H15: C | I15: =IF(OR(G15="",H15=""),"D",IF(OR(G15="D",H15="D"),"D",IF((CODE(G15)+CODE(H15)-130)<=3,"A",IF((CODE(G15)+CODE(H15)-130)=4,"B","C")))) -> B | J15: 0
A16: 15 | B16: REQ-CP-002 | C16: S | D16: pending | F16: iteration | G16: C | H16: C | I16: =IF(OR(G16="",H16=""),"D",IF(OR(G16="D",H16="D"),"D",IF((CODE(G16)+CODE(H16)-130)<=3,"A",IF((CODE(G16)+CODE(H16)-130)=4,"B","C")))) -> B | J16: 0
A17: 16 | B17: REQ-CP-002 | C17: +D | D17: pending | F17: iteration | G17: C | H17: C | I17: =IF(OR(G17="",H17=""),"D",IF(OR(G17="D",H17="D"),"D",IF((CODE(G17)+CODE(H17)-130)<=3,"A",IF((CODE(G17)+CODE(H17)-130)=4,"B","C")))) -> B | J17: 0
A18: 17 | B18: REQ-CP-002 | C18: +I | D18: pending | F18: iteration | G18: C | H18: C | I18: =IF(OR(G18="",H18=""),"D",IF(OR(G18="D",H18="D"),"D",IF((CODE(G18)+CODE(H18)-130)<=3,"A",IF((CODE(G18)+CODE(H18)-130)=4,"B","C")))) -> B | J18: 0
A19: 18 | B19: REQ-CP-002 | C19: +N | D19: pending | F19: iteration | G19: C | H19: C | I19: =IF(OR(G19="",H19=""),"D",IF(OR(G19="D",H19="D"),"D",IF((CODE(G19)+CODE(H19)-130)<=3,"A",IF((CODE(G19)+CODE(H19)-130)=4,"B","C")))) -> B | J19: 0
A20: 19 | B20: REQ-CP-002 | C20: +L | D20: pending | F20: iteration | G20: C | H20: C | I20: =IF(OR(G20="",H20=""),"D",IF(OR(G20="D",H20="D"),"D",IF((CODE(G20)+CODE(H20)-130)<=3,"A",IF((CODE(G20)+CODE(H20)-130)=4,"B","C")))) -> B | J20: 0
A21: 20 | B21: REQ-CP-002 | C21: +P_phys | D21: na | E21: +P_phys (physical-hardware constraints) N/A for web SUT | F21: none | G21: D | H21: D | I21: =IF(OR(G21="",H21=""),"D",IF(OR(G21="D",H21="D"),"D",IF((CODE(G21)+CODE(H21)-130)<=3,"A",IF((CODE(G21)+CODE(H21)-130)=4,"B","C")))) -> D | J21: 0
A22: 21 | B22: REQ-CP-003 | C22: F | D22: active | F22: iteration | G22: B | H22: B | I22: =IF(OR(G22="",H22=""),"D",IF(OR(G22="D",H22="D"),"D",IF((CODE(G22)+CODE(H22)-130)<=3,"A",IF((CODE(G22)+CODE(H22)-130)=4,"B","C")))) -> A | J22: 1
A23: 22 | B23: REQ-CP-003 | C23: U | D23: pending | F23: iteration | G23: C | H23: C | I23: =IF(OR(G23="",H23=""),"D",IF(OR(G23="D",H23="D"),"D",IF((CODE(G23)+CODE(H23)-130)<=3,"A",IF((CODE(G23)+CODE(H23)-130)=4,"B","C")))) -> B | J23: 0
A24: 23 | B24: REQ-CP-003 | C24: R | D24: pending | F24: iteration | G24: C | H24: C | I24: =IF(OR(G24="",H24=""),"D",IF(OR(G24="D",H24="D"),"D",IF((CODE(G24)+CODE(H24)-130)<=3,"A",IF((CODE(G24)+CODE(H24)-130)=4,"B","C")))) -> B | J24: 0
A25: 24 | B25: REQ-CP-003 | C25: P | D25: pending | F25: iteration | G25: C | H25: C | I25: =IF(OR(G25="",H25=""),"D",IF(OR(G25="D",H25="D"),"D",IF((CODE(G25)+CODE(H25)-130)<=3,"A",IF((CODE(G25)+CODE(H25)-130)=4,"B","C")))) -> B | J25: 0
A26: 25 | B26: REQ-CP-003 | C26: S | D26: active | F26: iteration | G26: B | H26: B | I26: =IF(OR(G26="",H26=""),"D",IF(OR(G26="D",H26="D"),"D",IF((CODE(G26)+CODE(H26)-130)<=3,"A",IF((CODE(G26)+CODE(H26)-130)=4,"B","C")))) -> A | J26: 1
A27: 26 | B27: REQ-CP-003 | C27: +D | D27: pending | F27: iteration | G27: C | H27: C | I27: =IF(OR(G27="",H27=""),"D",IF(OR(G27="D",H27="D"),"D",IF((CODE(G27)+CODE(H27)-130)<=3,"A",IF((CODE(G27)+CODE(H27)-130)=4,"B","C")))) -> B | J27: 0
A28: 27 | B28: REQ-CP-003 | C28: +I | D28: pending | F28: iteration | G28: C | H28: C | I28: =IF(OR(G28="",H28=""),"D",IF(OR(G28="D",H28="D"),"D",IF((CODE(G28)+CODE(H28)-130)<=3,"A",IF((CODE(G28)+CODE(H28)-130)=4,"B","C")))) -> B | J28: 0
A29: 28 | B29: REQ-CP-003 | C29: +N | D29: pending | F29: iteration | G29: C | H29: C | I29: =IF(OR(G29="",H29=""),"D",IF(OR(G29="D",H29="D"),"D",IF((CODE(G29)+CODE(H29)-130)<=3,"A",IF((CODE(G29)+CODE(H29)-130)=4,"B","C")))) -> B | J29: 0
A30: 29 | B30: REQ-CP-003 | C30: +L | D30: active | F30: iteration | G30: B | H30: B | I30: =IF(OR(G30="",H30=""),"D",IF(OR(G30="D",H30="D"),"D",IF((CODE(G30)+CODE(H30)-130)<=3,"A",IF((CODE(G30)+CODE(H30)-130)=4,"B","C")))) -> A | J30: 1
A31: 30 | B31: REQ-CP-003 | C31: +P_phys | D31: na | E31: +P_phys (physical-hardware constraints) N/A for web SUT | F31: none | G31: D | H31: D | I31: =IF(OR(G31="",H31=""),"D",IF(OR(G31="D",H31="D"),"D",IF((CODE(G31)+CODE(H31)-130)<=3,"A",IF((CODE(G31)+CODE(H31)-130)=4,"B","C")))) -> D | J31: 0
A32: 31 | B32: REQ-CP-004 | C32: F | D32: pending | F32: iteration | G32: C | H32: C | I32: =IF(OR(G32="",H32=""),"D",IF(OR(G32="D",H32="D"),"D",IF((CODE(G32)+CODE(H32)-130)<=3,"A",IF((CODE(G32)+CODE(H32)-130)=4,"B","C")))) -> B | J32: 0
A33: 32 | B33: REQ-CP-004 | C33: U | D33: active | F33: iteration | G33: B | H33: B | I33: =IF(OR(G33="",H33=""),"D",IF(OR(G33="D",H33="D"),"D",IF((CODE(G33)+CODE(H33)-130)<=3,"A",IF((CODE(G33)+CODE(H33)-130)=4,"B","C")))) -> A | J33: 1
A34: 33 | B34: REQ-CP-004 | C34: R | D34: pending | F34: iteration | G34: C | H34: C | I34: =IF(OR(G34="",H34=""),"D",IF(OR(G34="D",H34="D"),"D",IF((CODE(G34)+CODE(H34)-130)<=3,"A",IF((CODE(G34)+CODE(H34)-130)=4,"B","C")))) -> B | J34: 0
A35: 34 | B35: REQ-CP-004 | C35: P | D35: pending | F35: iteration | G35: C | H35: C | I35: =IF(OR(G35="",H35=""),"D",IF(OR(G35="D",H35="D"),"D",IF((CODE(G35)+CODE(H35)-130)<=3,"A",IF((CODE(G35)+CODE(H35)-130)=4,"B","C")))) -> B | J35: 0
A36: 35 | B36: REQ-CP-004 | C36: S | D36: pending | F36: iteration | G36: C | H36: C | I36: =IF(OR(G36="",H36=""),"D",IF(OR(G36="D",H36="D"),"D",IF((CODE(G36)+CODE(H36)-130)<=3,"A",IF((CODE(G36)+CODE(H36)-130)=4,"B","C")))) -> B | J36: 0
A37: 36 | B37: REQ-CP-004 | C37: +D | D37: pending | F37: iteration | G37: C | H37: C | I37: =IF(OR(G37="",H37=""),"D",IF(OR(G37="D",H37="D"),"D",IF((CODE(G37)+CODE(H37)-130)<=3,"A",IF((CODE(G37)+CODE(H37)-130)=4,"B","C")))) -> B | J37: 0
A38: 37 | B38: REQ-CP-004 | C38: +I | D38: active | F38: iteration | G38: B | H38: B | I38: =IF(OR(G38="",H38=""),"D",IF(OR(G38="D",H38="D"),"D",IF((CODE(G38)+CODE(H38)-130)<=3,"A",IF((CODE(G38)+CODE(H38)-130)=4,"B","C")))) -> A | J38: 1
A39: 38 | B39: REQ-CP-004 | C39: +N | D39: pending | F39: iteration | G39: C | H39: C | I39: =IF(OR(G39="",H39=""),"D",IF(OR(G39="D",H39="D"),"D",IF((CODE(G39)+CODE(H39)-130)<=3,"A",IF((CODE(G39)+CODE(H39)-130)=4,"B","C")))) -> B | J39: 0
A40: 39 | B40: REQ-CP-004 | C40: +L | D40: pending | F40: iteration | G40: C | H40: C | I40: =IF(OR(G40="",H40=""),"D",IF(OR(G40="D",H40="D"),"D",IF((CODE(G40)+CODE(H40)-130)<=3,"A",IF((CODE(G40)+CODE(H40)-130)=4,"B","C")))) -> B | J40: 0
...

Sheet 01c_StateMachine
A1: id | B1: kind | C1: name | D1: description_cs | E1: from_state | F1: to_state | G1: trigger | H1: integrations_invoked | I1: error_subreason | J1: related_tt_refs | K1: related_screen | L1: notes
A2: 1 | B2: state | C2: NEW | D2: Nový — ID hlášení založeno | K2: p27/133
A3: 2 | B3: state | C3: IN_PROGRESS_DRIVERS | D3: Rozpracováno — řidiči | K3: p27-35/133
A4: 3 | B4: state | C4: IN_PROGRESS_VEHICLES | D4: Rozpracováno — vozidla | K4: p35-40/133
A5: 4 | B5: state | C5: IN_PROGRESS_CIRCUMSTANCES | D5: Rozpracováno — okolnosti | K5: p40+/133
A6: 5 | B6: state | C6: TO_SIGN | D6: K podpisu — souhrn | K6: p41/133
A7: 6 | B7: state | C7: FINISHED | D7: Dokončeno — PDF odeslán | K7: p42/133
A8: 7 | B8: state | C8: CANCEL | D8: Zrušeno — user-abort | K8: menu Začít znovu
A9: 8 | B9: state | C9: ERROR | D9: Chyba — system-failure (sub-reason) | K9: různé
A10: 9 | B10: transition | C10: PING_OK | D10: INT-002 SMS Gateway PING happy | E10: (none) | F10: NEW | G10: PING_OK | H10: INT-002 | J10: TT-CP-R1-A1 | K10: 01_Potvrzení
A11: 10 | B11: transition | C11: PING_NOK | D11: INT-002 PING NOK | E11: (none) | F11: ERROR | G11: PING_NOK | H11: INT-002 | I11: smsGatewayUnavailable | J11: TT-CP-R1-A1 | K11: 01_Potvrzení
A12: 11 | B12: transition | C12: OTP_SENT_VERIFIED | D12: Both phones verified | E12: NEW | F12: IN_PROGRESS_DRIVERS | G12: OTP_SENT_VERIFIED | H12: INT-002 | J12: TT-CP-R1-A1 | K12: 02_Ověření
A13: 12 | B13: transition | C13: DRIVERS_CONFIRMED | D13: All drivers' identity loaded | E13: IN_PROGRESS_DRIVERS | F13: IN_PROGRESS_VEHICLES | G13: DRIVERS_CONFIRMED | H13: INT-006/007/004 | J13: TT-CP-R1-B | K13: 03-06
A14: 13 | B14: transition | C14: VEHICLES_CONFIRMED | D14: All vehicles' SPZ scanned + AISPOV happy | E14: IN_PROGRESS_VEHICLES | F14: IN_PROGRESS_CIRCUMSTANCES | G14: VEHICLES_CONFIRMED | H14: INT-006/007/004 | J14: TT-CP-R1-C | K14: 08-11
A15: 14 | B15: transition | C15: CIRCUMSTANCES_FILLED | D15: User confirmed summary | E15: IN_PROGRESS_CIRCUMSTANCES | F15: TO_SIGN | G15: CIRCUMSTANCES_FILLED | H15: INT-005/008 | J15: TT-CP-R1-D | K15: 12-15
A16: 15 | B16: transition | C16: SIGNED | D16: Both participants SMS-OTP signed | E16: TO_SIGN | F16: FINISHED | G16: SIGNED | H16: INT-002,003 | J16: TT-CP-R1-D | K16: 16-17
A17: 16 | B17: transition | C17: SMS_CODE_ATTEMPTS | D17: OTP retry exhaustion | E17: (any IN_PROGRESS_*) | F17: ERROR | G17: SMS_CODE_ATTEMPTS | H17: INT-002 | I17: SMS_CODE_ATTEMPTS | J17: TT-CP-R1-A2 | K17: 02
A18: 17 | B18: transition | C18: TELEPHONE_NUMBER_COUNT | D18: DB security: phone overused | E18: (during phone verify) | F18: ERROR | G18: TELEPHONE_NUMBER_COUNT | H18: (internal) | I18: TELEPHONE_NUMBER_COUNT | J18: TT-CP-R1-A2 | K18: 02
A19: 18 | B19: transition | C19: AISPOV_ROB_NENALEZENO | D19: ROB lookup not-found | E19: (during driver-data load) | F19: (stays in IN_PROGRESS_DRIVERS) | G19: AISPOV_ROB_NENALEZENO | H19: INT-004 | I19: AISPOV_ROB_NENALEZENO | J19: TT-CP-R1-B | K19: 04/06
A20: 19 | B20: transition | C20: USER_CANCELS | D20: User clicked Začít znovu + confirm | E20: (any IN_PROGRESS_*) | F20: CANCEL | G20: USER_CANCELS | H20: (internal) | J20: (R2) | K20: menu
A21: 20 | B21: transition | C21: OUTAGE_ACTIVE | D21: Azure Blob outage config active | E21: (at gateway D00) | F21: (no transition; CTA disabled) | G21: OUTAGE_ACTIVE | H21: INT-009 | I21: OUTAGE_ACTIVE | J21: TT-CP-R1-F | K21: D00

Sheet 02_TestCases
A1: id | B1: item_code | C1: item_name_cs | D1: item_name_en | E1: item_descr_cs | F1: item_descr_en | G1: comments_KP_en | H1: env | I1: ext_ws | J1: item_type | K1: item_status | L1: severity | M1: urgency | N1: priority | O1: submitter | P1: submit_date | Q1: test_target_ref | R1: type | S1: preconditions | T1: steps_summary | U1: expected_summary | V1: postconditions | W1: env_coverage | X1: viewport_spec | Y1: framework_targets | Z1: state_machine_terminal_state | AA1: state_error_subreason | AB1: dev_spec_path | AC1: last_run_date | AD1: last_run_verdict | AE1: created_at | AF1: updated_at | AG1: notes | AH1: furps_dimensions | AI1: impulse_ref | AJ1: diligence | AK1: env_constraints | AL1: applies_to_demo | AM1: applies_to_prod
A2: 1 | B2: TC-CP-001 | C2: PING SMS Gateway — happy | D2: PING SMS Gateway — happy | E2: Po stisku 'pokračovat' na screen 01: PING vrátí OK → vytvoří se ID hlášení (NEW) → přechod na screen 02. | F2: On 'continue' from screen 01: PING returns OK → report ID created (NEW) → advance to screen 02. | G2: On 'understand' from screen D01: PING returns OK → advance to screen D02. | H2: STANDARD | I2: N8 | J2: test_case | K2: draft | L2: A | M2: A | N2: A | O2: Petr | P2: 46147 | Q2: TT-CP-R1-A1 | R2: happy | S2: fresh browser; CS locale; tst.* reachable; reCAPTCHA bypass set | T2: see SPEC.md (deferred) | U2: see SPEC.md | V2: no record persisted unless terminal state = FINISHED | W2: TST + DMO | X2: 320 / 375 / 414 | Y2: playwright; cypress | Z2: NEW | AB2: specs/TC-CP-001-SPEC.md (rev pending) | AE2: 46147 | AF2: 46148 | AG2: Replaces rev3 TC-CP-001 (was wizard-entry smoke; now PING gate per analytical doc). | AH2: F,R | AI2: D01_step_PING | AJ2: happy | AL2: TRUE | AM2: TRUE
A3: 2 | B3: TC-CP-002 | C3: PING SMS Gateway — NOK (Endpage) | D3: PING SMS Gateway — NOK (Endpage) | E3: Mock SMS Gateway PING NOK → ERROR Endpage zobrazena → no advance, no state change. | F3: Mock SMS Gateway PING NOK → ERROR Endpage shown → no advance, no state change. | G3: Mock SMS Gateway PING NOK → ERROR Endpage shown → no advance, no state change. | H3: STANDARD | I3: N8 | J3: test_case | K3: draft | L3: A | M3: A | N3: A | O3: Petr | P3: 46147 | Q3: TT-CP-R1-A1 | R3: failure | S3: fresh browser; CS locale; tst.* reachable; reCAPTCHA bypass set | T3: see SPEC.md (deferred) | U3: see SPEC.md | V3: no record persisted unless terminal state = FINISHED | W3: TST + DMO | X3: 320 / 375 / 414 | Y3: playwright; cypress | Z3: n/a | AA3: PING_NOK | AB3: specs/TC-CP-002-SPEC.md (rev pending) | AE3: 46147 | AF3: 46148 | AG3: Pairs with TC-CP-001 per R-FAIL-1. | AH3: F,R | AI3: D01_step_PING | AJ3: negative | AL3: TRUE | AM3: TRUE
A4: 3 | B4: TC-CP-003 | C4: Ověření telefonu — happy oba účastníci | D4: Phone-OTP — happy both participants | E4: Účastník A: zadá CZ +420 9-digit číslo → OTP přijde → potvrdí. Účastník N: stejně. → IN_PROGRESS_DRIVERS. | F4: Driver A: enters CZ +420 9-digit number → OTP arrives → verified. Driver N: same. → IN_PROGRESS_DRIVERS. | G4: Participant A: enters CZ +420 9-digit number → OTP arrives → verified. Participant N: same. → advance to screen D03 | H4: STANDARD | I4: N8 | J4: test_case | K4: draft | L4: A | M4: A | N4: A | O4: Petr | P4: 46147 | Q4: TT-CP-R1-A2 | R4: happy | S4: fresh browser; CS locale; tst.* reachable; reCAPTCHA bypass set | T4: see SPEC.md (deferred) | U4: see SPEC.md | V4: no record persisted unless terminal state = FINISHED | W4: TST + DMO | X4: 320 / 375 / 414 | Y4: playwright; cypress | Z4: IN_PROGRESS_DRIVERS | AB4: specs/TC-CP-003-SPEC.md (rev pending) | AE4: 46147 | AF4: 46148 | AG4: Tightens rev3 TC-CP-003 to phone-OTP only (was full wizard E2E). | AH4: F,R | AI4: D02_step_OTP_verify | AJ4: happy | AL4: TRUE | AM4: TRUE
A5: 4 | B5: TC-CP-004 | C5: OTP — vyčerpání pokusů (SMS_CODE_ATTEMPTS) | D5: OTP — attempts exhausted (SMS_CODE_ATTEMPTS) | E5: Třikrát zadej špatný OTP → překročení limitu → ERROR Endpage; accidentReportStatus=ERROR/SMS_CODE_ATTEMPTS. | F5: Three wrong OTPs → limit exceeded → ERROR Endpage; accidentReportStatus=ERROR/SMS_CODE_ATTEMPTS. | G5: N wrong OTPs → limit exceeded N → ERROR/codes Endpage; accidentReportStatus=ERROR/SMS_CODE_ATTEMPTS. | H5: STANDARD | I5: N8 | J5: test_case | K5: draft | L5: A | M5: A | N5: A | O5: Petr | P5: 46147 | Q5: TT-CP-R1-A2 | R5: failure | S5: fresh browser; CS locale; tst.* reachable; reCAPTCHA bypass set | T5: see SPEC.md (deferred) | U5: see SPEC.md | V5: no record persisted unless terminal state = FINISHED | W5: TST + DMO | X5: 320 / 375 / 414 | Y5: playwright; cypress | Z5: ERROR | AA5: SMS_CODE_ATTEMPTS | AB5: specs/TC-CP-004-SPEC.md (rev pending) | AE5: 46147 | AF5: 46148 | AG5: Pairs with TC-CP-003. | AH5: F,R | AI5: D02_step_OTP_attempts | AJ5: negative | AL5: TRUE | AM5: TRUE
A6: 5 | B6: TC-CP-005 | C6: Telefonní číslo nadužíváno (TELEPHONE_NUMBER_COUNT) | D6: Phone number overused (TELEPHONE_NUMBER_COUNT) | E6: Použij číslo, které je v DB vícekrát než config-limit → ERROR Endpage; subreason=TELEPHONE_NUMBER_COUNT. | F6: Use a number present in DB more than the config limit → ERROR Endpage; subreason=TELEPHONE_NUMBER_COUNT. | G6: Use a number present in DB more than the config limit → ERROR Endpage; subreason=ERR_TOO_MANY_PHONE_NUMBER_OCCURRENCE. | H6: STANDARD | J6: test_case | K6: draft | L6: A | M6: B | N6: A | O6: Petr | P6: 46147 | Q6: TT-CP-R1-A2 | R6: failure | S6: fresh browser; CS locale; tst.* reachable; reCAPTCHA bypass set | T6: see SPEC.md (deferred) | U6: see SPEC.md | V6: no record persisted unless terminal state = FINISHED | W6: TST + DMO | X6: 320 / 375 / 414 | Y6: playwright; cypress | Z6: ERROR | AA6: TELEPHONE_NUMBER_COUNT | AB6: specs/TC-CP-005-SPEC.md (skeleton) | AE6: 46147 | AF6: 46148 | AG6: Security check; needs DB-seed fixture. | AH6: F,R | AI6: D02_step_OTP_send | AJ6: happy | AL6: TRUE | AM6: TRUE
A7: 6 | B7: TC-CP-006 | C7: SMS Gateway HTTP 422 EX_CHYBA | D7: SMS Gateway HTTP 422 EX_CHYBA | E7: Mock SMS Gateway → 422 + 'N8/2025/01: EX_CHYBA_TELCISLA_NEBO_SMSTEXTU' → inline error pod polem; no advance. | F7: Mock SMS Gateway → 422 + 'EX_CHYBA' → inline error under field; no advance. | G7: OK | H7: STANDARD | I7: N8 | J7: test_case | K7: draft | L7: B | M7: B | N7: B | O7: Petr | P7: 46147 | Q7: TT-CP-R1-A2 | R7: failure | S7: fresh browser; CS locale; tst.* reachable; reCAPTCHA bypass set | T7: see SPEC.md (deferred) | U7: see SPEC.md | V7: no record persisted unless terminal state = FINISHED | W7: TST + DMO | X7: 320 / 375 / 414 | Y7: playwright; cypress | Z7: n/a | AA7: EX_CHYBA | AB7: specs/TC-CP-006-SPEC.md (skeleton) | AE7: 46147 | AF7: 46148 | AG7: Inline-error path; not a state-machine ERROR. | AH7: F,R | AI7: D02_step_DB_freq | AJ7: negative | AL7: TRUE | AM7: TRUE
A8: 7 | B8: TC-CP-007 | C8: OTP retry happy (recoverable) | D8: OTP retry happy (recoverable) | E8: Zadej špatný OTP, pak správný → ověřený; pokus countdown -1; advance to next driver or screen 03. | F8: Wrong OTP then correct → verified; attempt count −1; advance to next driver or screen 03. | G8: Wrong OTP then correct → verified; attempt count −1; advance to next participant or screen D03. | H8: STANDARD | I8: N8 | J8: test_case | K8: draft | L8: A | M8: B | N8: A | O8: Petr | P8: 46147 | Q8: TT-CP-R1-A2 | R8: regression | S8: fresh browser; CS locale; tst.* reachable; reCAPTCHA bypass set | T8: see SPEC.md (deferred) | U8: see SPEC.md | V8: no record persisted unless terminal state = FINISHED | W8: TST + DMO | X8: 320 / 375 / 414 | Y8: playwright; cypress | Z8: IN_PROGRESS_DRIVERS | AB8: specs/TC-CP-007-SPEC.md (skeleton) | AE8: 46147 | AF8: 46148 | AG8: Recoverable subset of failure envelope. | AH8: F,R | AI8: D02_step_OTP_retry | AJ8: regression | AL8: TRUE | AM8: TRUE
A9: 8 | B9: TC-CP-008 | C9: zenID + AISPOV ROB — happy auto-fill | D9: zenID + AISPOV ROB — happy auto-fill | E9: Účastník nafotí OP → zenID OK → AISPOV StatusVysledek=OK → form pre-filled na screen 04. | F9: User photographs OP → zenID OK → AISPOV StatusVysledek=OK → form pre-filled at screen 04. | G9: User photographs OP → zenID OK → AISPOV StatusVysledek=OK → form pre-filled at screen D04. | H9: STANDARD | I9: zenID, AISPOV-AB | J9: test_case | K9: draft | L9: A | M9: A | N9: A | O9: Petr | P9: 46147 | Q9: TT-CP-R1-B | R9: happy | S9: fresh browser; CS locale; tst.* reachable; reCAPTCHA bypass set | T9: see SPEC.md (deferred) | U9: see SPEC.md | V9: no record persisted unless terminal state = FINISHED | W9: TST + DMO | X9: 320 / 375 / 414 | Y9: playwright; cypress | Z9: IN_PROGRESS_DRIVERS | AB9: specs/TC-CP-008-SPEC.md (skeleton) | AE9: 46147 | AF9: 46148 | AG9: Replaces rev3 TC-CP-001 framing — actual implicit-ID-auth happy. Strengthening (rev 6 / COVERAGE-GAP §4): assert exactly 1 AISPOV call per report when first ROB lookup returns NENALEZENO — no further AISPOV calls for participant N. Verify via network-trace count. | AH9: F,P,S | AI9: D04_step_AISPOV_ROB | AJ9: happy | AL9: TRUE | AM9: TRUE
A10: 9 | B10: TC-CP-009 | C10: zenID NOK → manual + AISPOV button — recoverable | D10: zenID NOK → manual + AISPOV button — recoverable | E10: zenID OCR NOK → editing mode → user fills jméno+příjmení+DOB+OP+addr → AISPOV button → ROB OK → pre-fill. | F10: zenID OCR NOK → editing mode → user fills basics → AISPOV button → ROB OK → pre-fill. | G10: zenID OCR NOK → editing mode → user fills basics → advance to next participant or screen D07 | H10: STANDARD | I10: zenID, AISPOV-AB | J10: test_case | K10: draft | L10: A | M10: A | N10: A | O10: Petr | P10: 46147 | Q10: TT-CP-R1-B | R10: regression | S10: fresh browser; CS locale; tst.* reachable; reCAPTCHA bypass set | T10: see SPEC.md (deferred) | U10: see SPEC.md | V10: no record persisted unless terminal state = FINISHED | W10: TST + DMO | X10: 320 / 375 / 414 | Y10: playwright; cypress | Z10: IN_PROGRESS_DRIVERS | AB10: specs/TC-CP-009-SPEC.md (skeleton) | AE10: 46147 | AF10: 46148 | AG10: Recoverable manual-fallback path. | AH10: F | AI10: D03_step_OCR_NOK | AJ10: regression | AL10: TRUE | AM10: TRUE
A11: 10 | B11: TC-CP-010 | C11: AISPOV NENALEZENO ROB — negativní bez auto-fill | D11: AISPOV NENALEZENO ROB — negative no auto-fill | E11: AISPOV vrátí NENALEZENO+SubStatus=OK+Komponenta=ROB → editing mode bez pre-fill; **no further AISPOV calls** for any participant in this report. | F11: AISPOV returns NENALEZENO+SubStatus=OK+Komponenta=ROB → editing mode no pre-fill; no further AISPOV calls. | G11: OK | H11: STANDARD | I11: AISPOV-AB | J11: test_case | K11: draft | L11: A | M11: A | N11: A | O11: Petr | P11: 46147 | Q11: TT-CP-R1-B | R11: failure | S11: fresh browser; CS locale; tst.* reachable; reCAPTCHA bypass set | T11: see SPEC.md (deferred) | U11: see SPEC.md | V11: no record persisted unless terminal state = FINISHED | W11: TST + DMO | X11: 320 / 375 / 414 | Y11: playwright; cypress | Z11: IN_PROGRESS_DRIVERS | AA11: AISPOV_ROB_NENALEZENO | AB11: specs/TC-CP-010-SPEC.md (skeleton) | AE11: 46147 | AF11: 46148 | AG11: Important: assert call-count = 1 across remainder of report. Pairs with TC-CP-008. | AH11: F,S | AI11: D04_step_AISPOV_NENALEZENO | AJ11: negative | AL11: TRUE | AM11: TRUE
A12: 11 | B12: TC-CP-011 | C12: Camera permission denied → gallery upload — recoverable | D12: Camera permission denied → gallery upload — recoverable | E12: Browser zakáže camera permission → CS error msg → user vybere gallery upload → flow pokračuje. | F12: Browser blocks camera → CS error → user selects gallery upload → flow continues. | G12: OK | H12: DEMO, STANDARD | J12: test_case | K12: draft | L12: A | M12: B | N12: A | O12: Petr | P12: 46147 | Q12: TT-CP-R1-B | R12: regression | S12: fresh browser; CS locale; tst.* reachable; reCAPTCHA bypass set | T12: see SPEC.md (deferred) | U12: see SPEC.md | V12: no record persisted unless terminal state = FINISHED | W12: TST + DMO | X12: 320 / 375 / 414 | Y12: playwright; cypress | Z12: IN_PROGRESS_DRIVERS | AB12: specs/TC-CP-011-SPEC.md (skeleton) | AE12: 46147 | AF12: 46148 | AG12: Mobile-only edge case; touch-target verification. | AH12: F,U,+I | AI12: D03_step_camera_perm | AJ12: regression | AL12: TRUE | AM12: TRUE
A13: 12 | B13: TC-CP-012 | C13: SPZ scan + AISPOV vehicle — happy | D13: SPZ scan + AISPOV vehicle — happy | E13: Nafotí SPZ → zenID OK → confirm popup ANO → AISPOV vehicle+insurance OK → form pre-filled na screen 09. | F13: Photograph SPZ → zenID OK → confirm popup YES → AISPOV vehicle+insurance OK → form pre-filled at screen 09. | G13: Photograph SPZ → zenID OK → confirm popup YES → AISPOV vehicle+insurance OK → form pre-filled at screen D09. | H13: STANDARD | I13: zenID, AISPOV-AB | J13: test_case | K13: draft | L13: A | M13: A | N13: A | O13: Petr | P13: 46147 | Q13: TT-CP-R1-C | R13: happy | S13: fresh browser; CS locale; tst.* reachable; reCAPTCHA bypass set | T13: see SPEC.md (deferred) | U13: see SPEC.md | V13: no record persisted unless terminal state = FINISHED | W13: TST + DMO | X13: 320 / 375 / 414 | Y13: playwright; cypress | Z13: IN_PROGRESS_CIRCUMSTANCES | AB13: specs/TC-CP-012-SPEC.md (skeleton) | AE13: 46147 | AF13: 46148 | AG13: Vehicle-side ID-auth analogue. Strengthening (rev 6 / COVERAGE-GAP §4): after SPZ confirm-popup ANO, assert SPZ photo upload UI is no longer interactable (re-upload disabled). | AH13: F,P | AI13: D08_step_SPZ_AISPOV | AJ13: happy | AL13: TRUE | AM13: TRUE
